Traceback (most recent call last):
  File "/hpc/mydata/yang-joon.kim/anaconda/23.1.0-3/x86_64/envs/snakemake/bin/snakemake", line 10, in <module>
    sys.exit(main())
             ^^^^^^
  File "/hpc/mydata/yang-joon.kim/anaconda/23.1.0-3/x86_64/envs/snakemake/lib/python3.11/site-packages/snakemake/__init__.py", line 3141, in main
    success = snakemake(
              ^^^^^^^^^^
  File "/hpc/mydata/yang-joon.kim/anaconda/23.1.0-3/x86_64/envs/snakemake/lib/python3.11/site-packages/snakemake/__init__.py", line 570, in snakemake
    update_config(overwrite_config, load_configfile(f))
                                    ^^^^^^^^^^^^^^^^^^
  File "/hpc/mydata/yang-joon.kim/anaconda/23.1.0-3/x86_64/envs/snakemake/lib/python3.11/site-packages/snakemake/io.py", line 1720, in load_configfile
    config = _load_configfile(configpath)
             ^^^^^^^^^^^^^^^^^^^^^^^^^^^^
  File "/hpc/mydata/yang-joon.kim/anaconda/23.1.0-3/x86_64/envs/snakemake/lib/python3.11/site-packages/snakemake/io.py", line 1694, in _load_configfile
    obj = open(configpath_or_obj, encoding="utf-8")
          ^^^^^^^^^^^^^^^^^^^^^^^^^^^^^^^^^^^^^^^^^
FileNotFoundError: [Errno 2] No such file or directory: '/hpc/projects/data.science/yangjoon.kim/zebrahub_multiome/data/processed_data/TDR118_merged_peaks/01_TDR118_merged_peaks.csv'
